kill: sending signal to 4905 failed: No such process
_GatheringFuture exception was never retrieved
future: <_GatheringFuture finished exception=CancelledError()>
concurrent.futures._base.CancelledError
_GatheringFuture exception was never retrieved
future: <_GatheringFuture finished exception=CancelledError()>
concurrent.futures._base.CancelledError
Logged in as Aproksimačka#8980


Sending Message: "Arduino Delavnice - 27.11.2021:
Pridruzite se arduino delavnicam, ki bodo 27.11.2021 ob 17.00 uri <@&905084973244117112>
Preostali cas: 7.24h"

Server: FE UNI
Succeeded in channels: ['arduino-delavnica']
Failed in channels: [] 
Timestamp: Date:27.11.2021 Time:10:00

----------------------------------
_GatheringFuture exception was never retrieved
future: <_GatheringFuture finished exception=NameError("name 'C_DAY_TO_SECOND' is not defined")>
Traceback (most recent call last):
  File "/home/ec2-user/python_scripts/selfpromotion_bot/framework.py", line 119, in advertiser
    l_ret = await l_server.advertise()
  File "/home/ec2-user/python_scripts/selfpromotion_bot/framework.py", line 89, in advertise
    l_text_to_send = l_msg.text() if callable(l_msg.text) else l_msg.text
  File "./main.py", line 14, in get_msg
    if l_time_left < C_DAY_TO_SECOND*3:
NameError: name 'C_DAY_TO_SECOND' is not defined
Logged in as Aproksimačka#8980
_GatheringFuture exception was never retrieved
future: <_GatheringFuture finished exception=NameError("name 'C_DAY_TO_SECOND' is not defined")>
Traceback (most recent call last):
  File "/home/ec2-user/python_scripts/selfpromotion_bot/framework.py", line 119, in advertiser
    l_ret = await l_server.advertise()
  File "/home/ec2-user/python_scripts/selfpromotion_bot/framework.py", line 89, in advertise
    l_text_to_send = l_msg.text() if callable(l_msg.text) else l_msg.text
  File "./main.py", line 14, in get_msg
    if l_time_left < C_DAY_TO_SECOND*3:
NameError: name 'C_DAY_TO_SECOND' is not defined
Logged in as Aproksimačka#8980
